<?xml version='1.0' encoding='utf-8'?>
<robot xmlns:xacro="http://www.ros.org/wiki/xacro" name="polar">
  <!-- safety_distance: Minimum safety distance in [m] by which the collision volumes are expanded and which is enforced during robot motions -->
  <!-- arm_id: Namespace of the polar arm. Serves to differentiate between arms in case of multiple instances. -->
  <xacro:macro name="polar_arm" params="arm_id:='polar' description_pkg:='polar_description' connected_to:='' xyz:='0 0 0' rpy:='0 0 0'">
    <xacro:unless value="${not connected_to}">
      <joint name="${arm_id}_joint_${connected_to}" type="fixed">
        <parent link="${connected_to}"/>
        <child link="${arm_id}_link0"/>
        <origin rpy="${rpy}" xyz="${xyz}"/>
      </joint>
    </xacro:unless>

    <xacro:property name="joint_damping" value="0.0"/>
    <xacro:property name="joint_friction" value="0.0"/>
    <xacro:property name="safety_k_position" value="100.0"/>
    <xacro:property name="safety_k_velocity" value="40.0"/>
    <xacro:property name="safety_pos_margin" value="0.0"/>

    <link name="world" />
    <joint name="robot_to_world" type="fixed">
      <parent link="world" />
      <child link="${arm_id}_link0" />
      <origin xyz="0.0 0.0 0.0" rpy="0.0 0.0 0.0" />
    </joint>

    <link name="${arm_id}_link0">
      <visual>
        <origin rpy="0 0 0" xyz="0 0 0"/>
        <geometry>
          <mesh filename="package://${description_pkg}/meshes/link0.dae"/>
        </geometry>
      </visual>
      <collision>
        <origin rpy="0 0 0" xyz="0 0 0"/>
        <geometry>
          <mesh filename="package://${description_pkg}/meshes/link0.dae"/>
        </geometry>
      </collision>
      <inertial>
        <origin rpy="0 0 0" xyz="-0.02 -0.013 0.035"/>
        <mass value="1.0"/>
        <inertia ixx="0.032" ixy="-0.003" ixz="0.0" iyy="0.029" iyz="0.001" izz="0.05"/>
      </inertial>
    </link>

    <link name="${arm_id}_link1">
      <visual>
        <origin rpy="0 0 0" xyz="-0.0 -0.0 -0.074"/>
        <geometry>
          <mesh filename="package://${description_pkg}/meshes/link1.dae"/>
        </geometry>
      </visual>
      <collision>
        <origin rpy="0 0 0" xyz="-0.0 -0.0 -0.074"/>
        <geometry>
          <mesh filename="package://${description_pkg}/meshes/link1.dae"/>
        </geometry>
      </collision>
      <inertial>
        <origin rpy="0 0 0" xyz="0.0 0.0 0.129"/>
        <mass value="1.0"/>
        <inertia ixx="0.006" ixy="0.0" ixz="0.0" iyy="0.005" iyz="0.0" izz="0.003"/>
      </inertial>
    </link>
    <joint name="${arm_id}_joint1" type="revolute">
      <safety_controller k_position="${safety_k_position}" k_velocity="${safety_k_velocity}" soft_lower_limit="${-pi + safety_pos_margin}" soft_upper_limit="${pi - safety_pos_margin}"/>
      <origin rpy="0 0 0" xyz="0.0 0.0 0.074"/>
      <parent link="${arm_id}_link0"/>
      <child link="${arm_id}_link1"/>
      <axis xyz="0.0 0.0 1.0"/>
      <limit effort="100" lower="${-pi}" upper="${pi}" velocity="0.1745"/> <!-- 10deg/s -->
      <dynamics damping="${joint_damping}" friction="${joint_friction}"/>
    </joint>

    <link name="${arm_id}_link2">
      <visual>
        <origin rpy="0 0 0" xyz="0.0 -0.0445 -0.199"/>
        <geometry>
          <mesh filename="package://${description_pkg}/meshes/link2.dae"/>
        </geometry>
      </visual>
      <collision>
        <origin rpy="0 0 0" xyz="0.0 -0.0445 -0.199"/>
        <geometry>
          <mesh filename="package://${description_pkg}/meshes/link2.dae"/>
        </geometry>
      </collision>
      <inertial>
        <origin rpy="0 0 0" xyz="-0.238 0.0 0.19"/>
        <mass value="1.0"/>
        <inertia ixx="0.082" ixy="0.0" ixz="0.0" iyy="1.288" iyz="0.0" izz="1.249"/>
      </inertial>
    </link>
    <joint name="${arm_id}_joint2" type="revolute">
      <safety_controller k_position="${safety_k_position}" k_velocity="${safety_k_velocity}" soft_lower_limit="${-pi + safety_pos_margin}" soft_upper_limit="${pi - safety_pos_margin}"/>
      <origin rpy="0 0 0" xyz="-0.0 0.0445 0.125"/>
      <parent link="${arm_id}_link1"/>
      <child link="${arm_id}_link2"/>
      <axis xyz="-0.0 1.0 -0.0"/>
      <limit effort="100" lower="${-pi}" upper="${pi}" velocity="0.1745"/> <!-- 10deg/s -->
      <dynamics damping="${joint_damping}" friction="${joint_friction}"/>
    </joint>

    <link name="${arm_id}_link3">
      <visual>
        <origin rpy="0 0 0" xyz="0.475211 -0.0445 -0.199"/>
        <geometry>
          <mesh filename="package://${description_pkg}/meshes/link3.dae"/>
        </geometry>
      </visual>
      <collision>
        <origin rpy="0 0 0" xyz="0.475211 -0.0445 -0.199"/>
        <geometry>
          <mesh filename="package://${description_pkg}/meshes/link3.dae"/>
        </geometry>
      </collision>
      <inertial>
        <origin rpy="0 0 0" xyz="0.232 0.0 0.304"/>
        <mass value="1.0"/>
        <inertia ixx="0.011" ixy="0.0" ixz="-0.02" iyy="0.154" iyz="0.0" izz="0.149"/>
      </inertial>
    </link>
    <joint name="${arm_id}_joint3" type="revolute">
      <safety_controller k_position="${safety_k_position}" k_velocity="${safety_k_velocity}" soft_lower_limit="${-pi + safety_pos_margin}" soft_upper_limit="${pi - safety_pos_margin}"/>
      <origin rpy="0 0 0" xyz="-0.475211 0.0 0.0"/>
      <parent link="${arm_id}_link2"/>
      <child link="${arm_id}_link3"/>
      <axis xyz="-0.0 -1.0 0.0"/>
      <limit effort="100" lower="${-pi}" upper="${pi}" velocity="0.1745"/> <!-- 10deg/s -->
      <dynamics damping="${joint_damping}" friction="${joint_friction}"/>
    </joint>

    <link name="${arm_id}_link4">
      <visual>
        <origin rpy="0 0 0" xyz="0.017457 -0.0 -0.300319"/>
        <geometry>
          <mesh filename="package://${description_pkg}/meshes/link4.dae"/>
        </geometry>
      </visual>
      <collision>
        <origin rpy="0 0 0" xyz="0.017457 -0.0 -0.300319"/>
        <geometry>
          <mesh filename="package://${description_pkg}/meshes/link4.dae"/>
        </geometry>
      </collision>
      <inertial>
        <origin rpy="0 0 0" xyz="0.025 0.0 0.30"/>
        <mass value="1.0"/>
        <inertia ixx="0.019" ixy="0.0" ixz="0.0" iyy="0.008" iyz="0.0" izz="0.024"/>
      </inertial>
    </link>
    <joint name="${arm_id}_joint4" type="revolute">
      <safety_controller k_position="${safety_k_position}" k_velocity="${safety_k_velocity}" soft_lower_limit="${-pi + safety_pos_margin}" soft_upper_limit="${pi - safety_pos_margin}"/>
      <origin rpy="0 0 0" xyz="0.457754 -0.0445 0.101319"/>
      <parent link="${arm_id}_link3"/>
      <child link="${arm_id}_link4"/>
      <axis xyz="1.0 -0.0 -0.0"/>
      <limit effort="100" lower="${-pi}" upper="${pi}" velocity="0.3491"/> <!-- 20deg/s -->
      <dynamics damping="${joint_damping}" friction="${joint_friction}"/>
    </joint>

    <link name="${arm_id}_link5">
      <visual>
        <origin rpy="0 0 0" xyz="-0.110443 -0.085 -0.300319"/>
        <geometry>
          <mesh filename="package://${description_pkg}/meshes/link5.dae"/>
        </geometry>
      </visual>
      <collision>
        <origin rpy="0 0 0" xyz="-0.110443 -0.085 -0.300319"/>
        <geometry>
          <mesh filename="package://${description_pkg}/meshes/link5.dae"/>
        </geometry>
      </collision>
      <inertial>
        <origin rpy="0 0 0" xyz="0.108 0.0 0.30"/>
        <mass value="1.0"/>
        <inertia ixx="0.006" ixy="0.0" ixz="0.0" iyy="0.005" iyz="0.0" izz="0.007"/>
      </inertial>
    </link>
    <joint name="${arm_id}_joint5" type="revolute">
      <safety_controller k_position="${safety_k_position}" k_velocity="${safety_k_velocity}" soft_lower_limit="${-pi + safety_pos_margin}" soft_upper_limit="${pi - safety_pos_margin}"/>
      <origin rpy="0 0 0" xyz="0.1279 0.085 0.0"/>
      <parent link="${arm_id}_link4"/>
      <child link="${arm_id}_link5"/>
      <axis xyz="0.0 -1.0 -0.0"/>
      <limit effort="100" lower="${-pi}" upper="${pi}" velocity="0.1745"/> <!-- 10deg/s -->
      <dynamics damping="${joint_damping}" friction="${joint_friction}"/>
    </joint>

    <link name="${arm_id}_link6">
      <visual>
        <origin rpy="0 0 0" xyz="-0.155443 -0.0 -0.300319"/>
        <geometry>
          <mesh filename="package://${description_pkg}/meshes/link6.dae"/>
        </geometry>
      </visual>
      <collision>
        <origin rpy="0 0 0" xyz="-0.155443 -0.0 -0.300319"/>
        <geometry>
          <mesh filename="package://${description_pkg}/meshes/link6.dae"/>
        </geometry>
      </collision>
      <inertial>
        <origin rpy="0 0 0" xyz="0.161 0.0 0.30"/>
        <mass value="1.0"/>
        <inertia ixx="0.0" ixy="0.0" ixz="0.0" iyy="0.0" iyz="0.0" izz="0.0"/>
      </inertial>
    </link>
    <joint name="${arm_id}_joint6" type="revolute">
      <safety_controller k_position="${safety_k_position}" k_velocity="${safety_k_velocity}" soft_lower_limit="${-pi + safety_pos_margin}" soft_upper_limit="${pi - safety_pos_margin}"/>
      <origin rpy="0 0 0" xyz="0.045 -0.085 0.0"/>
      <parent link="${arm_id}_link5"/>
      <child link="${arm_id}_link6"/>
      <axis xyz="1.0 0.0 -0.0"/>
      <limit effort="100" lower="${-pi}" upper="${pi}" velocity="0.1745"/> <!-- 10deg/s -->
      <dynamics damping="${joint_damping}" friction="${joint_friction}"/>
    </joint>

  </xacro:macro>
</robot>
