<?xml version='1.0' encoding='utf-8'?>
<robot xmlns:xacro="http://www.ros.org/wiki/xacro" name="polar">
  <!-- safety_distance: Minimum safety distance in [m] by which the collision volumes are expanded and which is enforced during robot motions -->
  <!-- arm_id: Namespace of the polar arm. Serves to differentiate between arms in case of multiple instances. -->
  <xacro:macro name="polar_arm" params="arm_id:='polar' description_pkg:='polar_description' connected_to:='' xyz:='0 0 0' rpy:='0 0 0'">
    <xacro:unless value="${not connected_to}">
      <joint name="${arm_id}_joint_${connected_to}" type="fixed">
        <parent link="${connected_to}"/>
        <child link="${arm_id}_link0"/>
        <origin rpy="${rpy}" xyz="${xyz}"/>
      </joint>
    </xacro:unless>

    <link name="${arm_id}_link0">
      <visual>
        <origin rpy="0 0 0" xyz="0 0 0"/>
        <geometry>
          <mesh filename="package://${description_pkg}/meshes/link0.dae"/>
        </geometry>
      </visual>
      <collision>
        <origin rpy="0 0 0" xyz="0 0 0"/>
        <geometry>
          <mesh filename="package://${description_pkg}/meshes/link0.dae"/>
        </geometry>
      </collision>
    </link>

    <link name="${arm_id}_link1">
      <visual>
        <origin rpy="0 0 0" xyz="-0.0 -0.0 -0.074"/>
        <geometry>
          <mesh filename="package://${description_pkg}/meshes/link1.dae"/>
        </geometry>
      </visual>
      <collision>
        <origin rpy="0 0 0" xyz="-0.0 -0.0 -0.074"/>
        <geometry>
          <mesh filename="package://${description_pkg}/meshes/link1.dae"/>
        </geometry>
      </collision>
    </link>
    <joint name="${arm_id}_joint1" type="revolute">
      <origin rpy="0 0 0" xyz="0.0 0.0 0.074"/>
      <parent link="${arm_id}_link0"/>
      <child link="${arm_id}_link1"/>
      <axis xyz="0.0 0.0 1.0"/>
      <limit effort="87" lower="${-pi}" upper="${pi}" velocity="2.1750"/>
    </joint>

    <link name="${arm_id}_link2">
      <visual>
        <origin rpy="0 0 0" xyz="0.0 -0.0445 -0.199"/>
        <geometry>
          <mesh filename="package://${description_pkg}/meshes/link2.dae"/>
        </geometry>
      </visual>
      <collision>
        <origin rpy="0 0 0" xyz="0.0 -0.0445 -0.199"/>
        <geometry>
          <mesh filename="package://${description_pkg}/meshes/link2.dae"/>
        </geometry>
      </collision>
    </link>
    <joint name="${arm_id}_joint2" type="revolute">
      <origin rpy="0 0 0" xyz="-0.0 0.0445 0.125"/>
      <parent link="${arm_id}_link1"/>
      <child link="${arm_id}_link2"/>
      <axis xyz="-0.0 1.0 -0.0"/>
      <limit effort="87" lower="${-pi}" upper="${pi}" velocity="2.1750"/>
    </joint>

    <link name="${arm_id}_link3">
      <visual>
        <origin rpy="0 0 0" xyz="0.475211 -0.0445 -0.199"/>
        <geometry>
          <mesh filename="package://${description_pkg}/meshes/link3.dae"/>
        </geometry>
      </visual>
      <collision>
        <origin rpy="0 0 0" xyz="0.475211 -0.0445 -0.199"/>
        <geometry>
          <mesh filename="package://${description_pkg}/meshes/link3.dae"/>
        </geometry>
      </collision>
    </link>
    <joint name="${arm_id}_joint3" type="revolute">
      <origin rpy="0 0 0" xyz="-0.475211 0.0 0.0"/>
      <parent link="${arm_id}_link2"/>
      <child link="${arm_id}_link3"/>
      <axis xyz="-0.0 -1.0 0.0"/>
      <limit effort="87" lower="${-pi}" upper="${pi}" velocity="2.1750"/>
    </joint>

    <link name="${arm_id}_link4">
      <visual>
        <origin rpy="0 0 0" xyz="0.017457 -0.0 -0.300319"/>
        <geometry>
          <mesh filename="package://${description_pkg}/meshes/link4.dae"/>
        </geometry>
      </visual>
      <collision>
        <origin rpy="0 0 0" xyz="0.017457 -0.0 -0.300319"/>
        <geometry>
          <mesh filename="package://${description_pkg}/meshes/link4.dae"/>
        </geometry>
      </collision>
    </link>
    <joint name="${arm_id}_joint4" type="revolute">
      <origin rpy="0 0 0" xyz="0.457754 -0.0445 0.101319"/>
      <parent link="${arm_id}_link3"/>
      <child link="${arm_id}_link4"/>
      <axis xyz="1.0 -0.0 -0.0"/>
      <limit effort="87" lower="${-pi}" upper="${pi}" velocity="2.1750"/>
    </joint>

    <link name="${arm_id}_link5">
      <visual>
        <origin rpy="0 0 0" xyz="-0.110443 -0.085 -0.300319"/>
        <geometry>
          <mesh filename="package://${description_pkg}/meshes/link5.dae"/>
        </geometry>
      </visual>
      <collision>
        <origin rpy="0 0 0" xyz="-0.110443 -0.085 -0.300319"/>
        <geometry>
          <mesh filename="package://${description_pkg}/meshes/link5.dae"/>
        </geometry>
      </collision>
    </link>
    <joint name="${arm_id}_joint5" type="revolute">
      <origin rpy="0 0 0" xyz="0.1279 0.085 0.0"/>
      <parent link="${arm_id}_link4"/>
      <child link="${arm_id}_link5"/>
      <axis xyz="0.0 -1.0 -0.0"/>
      <limit effort="12" lower="${-pi}" upper="${pi}" velocity="2.6100"/>
    </joint>

    <link name="${arm_id}_link6">
      <visual>
        <origin rpy="0 0 0" xyz="-0.155443 -0.0 -0.300319"/>
        <geometry>
          <mesh filename="package://${description_pkg}/meshes/link6.dae"/>
        </geometry>
      </visual>
      <collision>
        <origin rpy="0 0 0" xyz="-0.155443 -0.0 -0.300319"/>
        <geometry>
          <mesh filename="package://${description_pkg}/meshes/link6.dae"/>
        </geometry>
      </collision>
    </link>
    <joint name="${arm_id}_joint6" type="revolute">
      <origin rpy="0 0 0" xyz="0.045 -0.085 0.0"/>
      <parent link="${arm_id}_link5"/>
      <child link="${arm_id}_link6"/>
      <axis xyz="1.0 0.0 -0.0"/>
      <limit effort="12" lower="${-pi}" upper="${pi}" velocity="2.6100"/>
    </joint>

  </xacro:macro>
</robot>
